<sdf version='1.6'>
  <world name='default'>
    <model name='ground_plane'>
      <static>1</static>
      <link name='link'>
        <collision name='collision'>
          <geometry>
            <plane>
              <normal>0 0 1</normal>
              <size>100 100</size>
            </plane>
          </geometry>
          <surface>
            <friction>
              <ode>
                <mu>100</mu>
                <mu2>50</mu2>
              </ode>
              <torsional>
                <ode/>
              </torsional>
            </friction>
            <contact>
              <ode/>
            </contact>
            <bounce/>
          </surface>
          <max_contacts>10</max_contacts>
        </collision>
        <visual name='visual'>
          <cast_shadows>0</cast_shadows>
          <geometry>
            <plane>
              <normal>0 0 1</normal>
              <size>100 100</size>
            </plane>
          </geometry>
          <material>
            <script>
              <uri>file://media/materials/scripts/gazebo.material</uri>
              <name>Gazebo/Grey</name>
            </script>
          </material>
        </visual>
        <self_collide>0</self_collide>
        <enable_wind>0</enable_wind>
        <kinematic>0</kinematic>
      </link>
    </model>
    <light name='sun' type='directional'>
      <cast_shadows>1</cast_shadows>
      <pose frame=''>0 0 10 0 -0 0</pose>
      <diffuse>0.8 0.8 0.8 1</diffuse>
      <specular>0.2 0.2 0.2 1</specular>
      <attenuation>
        <range>1000</range>
        <constant>0.9</constant>
        <linear>0.01</linear>
        <quadratic>0.001</quadratic>
      </attenuation>
      <direction>-0.5 0.1 -0.9</direction>
    </light>
    <gui fullscreen='0'>
      <camera name='user_camera'>
        <pose frame=''>-5.68694 -0.381541 2.95616 0 0.689796 0.324156</pose>
        <view_controller>orbit</view_controller>
        <projection_type>perspective</projection_type>
      </camera>
    </gui>
    <gravity>0 0 -9.8</gravity>
    <magnetic_field>6e-06 2.3e-05 -4.2e-05</magnetic_field>
    <atmosphere type='adiabatic'/>
    <physics name='default_physics' default='0' type='ode'>
      <max_step_size>0.001</max_step_size>
      <real_time_factor>1</real_time_factor>
      <real_time_update_rate>1000</real_time_update_rate>
    </physics>
    <scene>
      <ambient>0.4 0.4 0.4 1</ambient>
      <background>0.7 0.7 0.7 1</background>
      <shadows>1</shadows>
    </scene>
    <wind/>
    <spherical_coordinates>
      <surface_model>EARTH_WGS84</surface_model>
      <latitude_deg>0</latitude_deg>
      <longitude_deg>0</longitude_deg>
      <elevation>0</elevation>
      <heading_deg>0</heading_deg>
    </spherical_coordinates>
    <model name='bookshelf'>
      <static>1</static>
      <link name='link'>
        <inertial>
          <mass>1</mass>
        </inertial>
        <collision name='back'>
          <pose frame=''>0 0.005 0.6 0 -0 0</pose>
          <geometry>
            <box>
              <size>0.9 0.01 1.2</size>
            </box>
          </geometry>
          <max_contacts>10</max_contacts>
          <surface>
            <contact>
              <ode/>
            </contact>
            <bounce/>
            <friction>
              <torsional>
                <ode/>
              </torsional>
              <ode/>
            </friction>
          </surface>
        </collision>
        <visual name='visual1'>
          <pose frame=''>0 0.005 0.6 0 -0 0</pose>
          <geometry>
            <box>
              <size>0.9 0.01 1.2</size>
            </box>
          </geometry>
          <material>
            <script>
              <uri>file://media/materials/scripts/gazebo.material</uri>
              <name>Gazebo/Wood</name>
            </script>
          </material>
        </visual>
        <collision name='left_side'>
          <pose frame=''>0.45 -0.195 0.6 0 -0 0</pose>
          <geometry>
            <box>
              <size>0.02 0.4 1.2</size>
            </box>
          </geometry>
          <max_contacts>10</max_contacts>
          <surface>
            <contact>
              <ode/>
            </contact>
            <bounce/>
            <friction>
              <torsional>
                <ode/>
              </torsional>
              <ode/>
            </friction>
          </surface>
        </collision>
        <visual name='visual2'>
          <pose frame=''>0.45 -0.195 0.6 0 -0 0</pose>
          <geometry>
            <box>
              <size>0.02 0.4 1.2</size>
            </box>
          </geometry>
          <material>
            <script>
              <uri>file://media/materials/scripts/gazebo.material</uri>
              <name>Gazebo/Wood</name>
            </script>
          </material>
        </visual>
        <collision name='right_side'>
          <pose frame=''>-0.45 -0.195 0.6 0 -0 0</pose>
          <geometry>
            <box>
              <size>0.02 0.4 1.2</size>
            </box>
          </geometry>
          <max_contacts>10</max_contacts>
          <surface>
            <contact>
              <ode/>
            </contact>
            <bounce/>
            <friction>
              <torsional>
                <ode/>
              </torsional>
              <ode/>
            </friction>
          </surface>
        </collision>
        <visual name='visual3'>
          <pose frame=''>-0.45 -0.195 0.6 0 -0 0</pose>
          <geometry>
            <box>
              <size>0.02 0.4 1.2</size>
            </box>
          </geometry>
          <material>
            <script>
              <uri>file://media/materials/scripts/gazebo.material</uri>
              <name>Gazebo/Wood</name>
            </script>
          </material>
        </visual>
        <collision name='bottom'>
          <pose frame=''>0 -0.195 0.03 0 -0 0</pose>
          <geometry>
            <box>
              <size>0.88 0.4 0.06</size>
            </box>
          </geometry>
          <max_contacts>10</max_contacts>
          <surface>
            <contact>
              <ode/>
            </contact>
            <bounce/>
            <friction>
              <torsional>
                <ode/>
              </torsional>
              <ode/>
            </friction>
          </surface>
        </collision>
        <visual name='visual4'>
          <pose frame=''>0 -0.195 0.03 0 -0 0</pose>
          <geometry>
            <box>
              <size>0.88 0.4 0.06</size>
            </box>
          </geometry>
          <material>
            <script>
              <uri>file://media/materials/scripts/gazebo.material</uri>
              <name>Gazebo/Wood</name>
            </script>
          </material>
        </visual>
        <collision name='top'>
          <pose frame=''>0 -0.195 1.19 0 -0 0</pose>
          <geometry>
            <box>
              <size>0.88 0.4 0.02</size>
            </box>
          </geometry>
          <max_contacts>10</max_contacts>
          <surface>
            <contact>
              <ode/>
            </contact>
            <bounce/>
            <friction>
              <torsional>
                <ode/>
              </torsional>
              <ode/>
            </friction>
          </surface>
        </collision>
        <visual name='visual5'>
          <pose frame=''>0 -0.195 1.19 0 -0 0</pose>
          <geometry>
            <box>
              <size>0.88 0.4 0.02</size>
            </box>
          </geometry>
          <material>
            <script>
              <uri>file://media/materials/scripts/gazebo.material</uri>
              <name>Gazebo/Wood</name>
            </script>
          </material>
        </visual>
        <collision name='low_shelf'>
          <pose frame=''>0 -0.195 0.43 0 -0 0</pose>
          <geometry>
            <box>
              <size>0.88 0.4 0.02</size>
            </box>
          </geometry>
          <max_contacts>10</max_contacts>
          <surface>
            <contact>
              <ode/>
            </contact>
            <bounce/>
            <friction>
              <torsional>
                <ode/>
              </torsional>
              <ode/>
            </friction>
          </surface>
        </collision>
        <visual name='visual6'>
          <pose frame=''>0 -0.195 0.43 0 -0 0</pose>
          <geometry>
            <box>
              <size>0.88 0.4 0.02</size>
            </box>
          </geometry>
          <material>
            <script>
              <uri>file://media/materials/scripts/gazebo.material</uri>
              <name>Gazebo/Wood</name>
            </script>
          </material>
        </visual>
        <collision name='high_shelf'>
          <pose frame=''>0 -0.195 0.8 0 -0 0</pose>
          <geometry>
            <box>
              <size>0.88 0.4 0.02</size>
            </box>
          </geometry>
          <max_contacts>10</max_contacts>
          <surface>
            <contact>
              <ode/>
            </contact>
            <bounce/>
            <friction>
              <torsional>
                <ode/>
              </torsional>
              <ode/>
            </friction>
          </surface>
        </collision>
        <visual name='visual7'>
          <pose frame=''>0 -0.195 0.8 0 -0 0</pose>
          <geometry>
            <box>
              <size>0.88 0.4 0.02</size>
            </box>
          </geometry>
          <material>
            <script>
              <uri>file://media/materials/scripts/gazebo.material</uri>
              <name>Gazebo/Wood</name>
            </script>
          </material>
        </visual>
        <self_collide>0</self_collide>
        <enable_wind>0</enable_wind>
        <kinematic>0</kinematic>
      </link>
      <pose frame=''>-0.081083 0.759561 0 0 -0 0</pose>
    </model>
    <state world_name='default'>
      <sim_time>1144 0</sim_time>
      <real_time>321 448669433</real_time>
      <wall_time>1601898120 110966301</wall_time>
      <iterations>313465</iterations>
      <model name='bookshelf'>
        <pose frame=''>0.4762 0.73923 0 0 -0 0</pose>
        <scale>1 1 1</scale>
        <link name='link'>
          <pose frame=''>0.4762 0.73923 -0 0 -0 0</pose>
          <velocity>0 0 0 0 -0 0</velocity>
          <acceleration>0 0 0 0 -0 0</acceleration>
          <wrench>0 0 0 0 -0 0</wrench>
        </link>
      </model>
      <model name='ground_plane'>
        <pose frame=''>0 0 0 0 -0 0</pose>
        <scale>1 1 1</scale>
        <link name='link'>
          <pose frame=''>0 0 0 0 -0 0</pose>
          <velocity>0 0 0 0 -0 0</velocity>
          <acceleration>0 0 0 0 -0 0</acceleration>
          <wrench>0 0 0 0 -0 0</wrench>
        </link>
      </model>
      <model name='j2s7s300'>
        <pose frame=''>-4e-06 2e-06 1e-06 1.7e-05 3.1e-05 0</pose>
        <scale>1 1 1</scale>
        <link name='j2s7s300_link_1'>
          <pose frame=''>-4e-06 3e-06 0.15675 -3.14156 6e-05 -3.14153</pose>
          <velocity>1e-06 -1e-06 -0.000118 0.000334 0.000678 9e-05</velocity>
          <acceleration>0.033976 -0.026324 -0.114565 0.397236 0.598629 0.088103</acceleration>
          <wrench>0.025404 -0.019683 -0.08566 0 -0 0</wrench>
        </link>
        <link name='j2s7s300_link_2'>
          <pose frame=''>-1.8e-05 0.001609 0.2755 -1.57073 -0.241521 -3.14155</pose>
          <velocity>4e-05 -1.7e-05 -0.000103 6.5e-05 -0.011006 0.000162</velocity>
          <acceleration>0.03966 -0.034345 -0.099493 0.364319 0.010702 1.10966</acceleration>
          <wrench>0.033501 -0.029011 -0.084041 0 -0 0</wrench>
        </link>
        <link name='j2s7s300_link_3'>
          <pose frame=''>0.049005 0.001628 0.474551 -3.14151 -0.241489 -3.14154</pose>
          <velocity>-0.002163 -7e-06 0.000445 -0.001216 -0.011181 -0.004631</velocity>
          <acceleration>0.041962 -0.027998 -0.091745 0.03395 -0.07388 0.098842</acceleration>
          <wrench>0.035445 -0.02365 -0.077497 0 -0 0</wrench>
        </link>
        <link name='j2s7s300_link_4'>
          <pose frame=''>0.098031 0.001647 0.673591 -1.5726 1.54148 -0.001774</pose>
          <velocity>-0.004395 9e-06 0.001018 -0.001156 -0.016459 -0.004734</velocity>
          <acceleration>0.025844 -0.020078 -0.039555 0.300011 -0.013843 -0.042175</acceleration>
          <wrench>0.017478 -0.013579 -0.026751 0 -0 0</wrench>
        </link>
        <link name='j2s7s300_link_5'>
          <pose frame=''>-0.10918 -0.009759 0.6675 1.53733 0.499018 1.55481</pose>
          <velocity>-0.00435 0.000985 -0.002371 -0.000216 -0.016397 -0.004697</velocity>
          <acceleration>0.024437 -0.007216 0.004138 0.193887 0.170568 -0.004383</acceleration>
          <wrench>0.011314 -0.003341 0.001916 0 -0 0</wrench>
        </link>
        <link name='j2s7s300_link_6'>
          <pose frame=''>-0.212885 -0.009766 0.66444 -0.489331 -0.110585 -0.150642</pose>
          <velocity>-0.004301 0.00146 -0.004088 -0.001463 -0.019031 -0.009997</velocity>
          <acceleration>0.022059 -0.04178 -0.033276 -0.934699 0.076159 -0.169987</acceleration>
          <wrench>0.010213 -0.019344 -0.015407 0 -0 0</wrench>
        </link>
        <link name='j2s7s300_link_7'>
          <pose frame=''>-0.193821 0.079964 0.615965 -1.08138 0.110549 2.99094</pose>
          <velocity>-0.00248 0.001192 -0.003875 -0.002026 -0.020508 -0.009206</velocity>
          <acceleration>0.021973 -0.110217 -0.166263 -1.00303 1.03835 -1.8955</acceleration>
          <wrench>0.021753 -0.109115 -0.164601 0 -0 0</wrench>
        </link>
        <link name='j2s7s300_link_finger_1'>
          <pose frame=''>-0.174688 0.164565 0.534644 1.6537 0.408743 1.35415</pose>
          <velocity>-6e-06 0.000816 -0.003743 -0.00722 -0.019715 -0.009653</velocity>
          <acceleration>0.074773 -0.22065 -0.337455 0.75874 -0.08567 0.601346</acceleration>
          <wrench>0.000748 -0.002207 -0.003375 0 -0 0</wrench>
        </link>
        <link name='j2s7s300_link_finger_2'>
          <pose frame=''>-0.195297 0.195583 0.583617 -1.89457 0.560622 1.33346</pose>
          <velocity>-0.000911 0.00397 -0.002417 1.36158 -0.097228 0.384576</velocity>
          <acceleration>-8.55481 27.2562 33.9841 2.33098 0.394118 -1.5096</acceleration>
          <wrench>-0.085548 0.272562 0.339841 0 -0 0</wrench>
        </link>
        <link name='j2s7s300_link_finger_3'>
          <pose frame=''>-0.151545 0.188927 0.588521 -1.50843 0.565605 1.36707</pose>
          <velocity>-0.000835 0.000195 -0.00353 -0.590074 0.122041 0.023349</velocity>
          <acceleration>-1.9548 -7.23614 -12.1917 2.86163 1.00757 0.413485</acceleration>
          <wrench>-0.019548 -0.072361 -0.121917 0 -0 0</wrench>
        </link>
        <link name='j2s7s300_link_finger_tip_1'>
          <pose frame=''>-0.166509 0.202892 0.514416 1.65372 0.40888 1.35417</pose>
          <velocity>0.000743 0.000559 -0.003871 -0.008108 -0.019321 -0.009222</velocity>
          <acceleration>0.108126 -0.202942 -0.161759 0.275857 -0.184254 1.80638</acceleration>
          <wrench>0.001081 -0.002029 -0.001618 0 -0 0</wrench>
        </link>
        <link name='j2s7s300_link_finger_tip_2'>
          <pose frame=''>-0.187106 0.233521 0.562641 -1.89845 0.578364 1.32627</pose>
          <velocity>-0.013319 0.039368 0.051615 2.96139 0.18495 -0.932728</velocity>
          <acceleration>0.062305 -3.80711 -5.02847 -0.079408 0.482891 0.17925</acceleration>
          <wrench>0.000623 -0.038071 -0.050285 0 -0 0</wrench>
        </link>
        <link name='j2s7s300_link_finger_tip_3'>
          <pose frame=''>-0.143519 0.22685 0.56747 -1.50805 0.575359 1.36777</pose>
          <velocity>-0.004347 -0.012988 -0.027049 1.38571 -0.356406 -0.085254</velocity>
          <acceleration>1.38799 2.88844 -0.447254 0.522276 1.39948 -0.451118</acceleration>
          <wrench>0.01388 0.028884 -0.004473 0 -0 0</wrench>
        </link>
        <link name='root'>
          <pose frame=''>-4e-06 2e-06 1e-06 1.7e-05 3.1e-05 0</pose>
          <velocity>-5.3e-05 3.4e-05 -0.000127 0.000354 0.000632 -9e-06</velocity>
          <acceleration>0.025558 -0.012368 -0.127352 0.385182 0.651928 -0.005799</acceleration>
          <wrench>0.011957 -0.005786 -0.05958 0 -0 0</wrench>
        </link>
      </model>
      <model name='kinect'>
        <pose frame=''>-0.948738 -0.990734 0.523789 0.003172 0.628362 1.56841</pose>
        <scale>1 1 1</scale>
        <link name='link'>
          <pose frame=''>-0.948738 -0.990734 0.523789 0.003172 0.628362 1.56841</pose>
          <velocity>6e-06 7.1e-05 0.000291 -0.00197 0.000179 0</velocity>
          <acceleration>0 0 0 0 -0 0</acceleration>
          <wrench>0 0 0 0 -0 0</wrench>
        </link>
      </model>
      <light name='sun'>
        <pose frame=''>0 0 10 0 -0 0</pose>
      </light>
    </state>
    <model name='j2s7s300'>
      <link name='root'>
        <pose frame=''>0 0 0 0 -0 0</pose>
        <inertial>
          <pose frame=''>0 0 0.1255 0 -0 0</pose>
          <mass>0.46784</mass>
          <inertia>
            <ixx>0.000951271</ixx>
            <ixy>0</ixy>
            <ixz>0</ixz>
            <iyy>0.000951271</iyy>
            <iyz>0</iyz>
            <izz>0.000374272</izz>
          </inertia>
        </inertial>
        <collision name='root_fixed_joint_lump__j2s7s300_link_base_collision'>
          <pose frame=''>0 0 0 0 -0 0</pose>
          <geometry>
            <mesh>
              <scale>1 1 1</scale>
              <uri>/home/siqihu/MasterThesis/ma-siqi/ros_ws/src/kinova/kinova_description/meshes/base.dae</uri>
            </mesh>
          </geometry>
          <max_contacts>10</max_contacts>
          <surface>
            <contact>
              <ode/>
            </contact>
            <bounce/>
            <friction>
              <torsional>
                <ode/>
              </torsional>
              <ode/>
            </friction>
          </surface>
        </collision>
        <visual name='root_fixed_joint_lump__j2s7s300_link_base_visual'>
          <pose frame=''>0 0 0 0 -0 0</pose>
          <geometry>
            <mesh>
              <scale>1 1 1</scale>
              <uri>/home/siqihu/MasterThesis/ma-siqi/ros_ws/src/kinova/kinova_description/meshes/base.dae</uri>
            </mesh>
          </geometry>
        </visual>
        <self_collide>0</self_collide>
        <enable_wind>0</enable_wind>
        <kinematic>0</kinematic>
      </link>
      <joint name='connect_root_and_world' type='fixed'>
        <child>root</child>
        <parent>world</parent>
      </joint>
      <link name='j2s7s300_link_1'>
        <pose frame=''>0 0 0.15675 3.14159 -0 3.14159</pose>
        <inertial>
          <pose frame=''>0 -0.002 -0.0605 0 -0 0</pose>
          <mass>0.7477</mass>
          <inertia>
            <ixx>0.00152032</ixx>
            <ixy>0</ixy>
            <ixz>0</ixz>
            <iyy>0.00152032</iyy>
            <iyz>0</iyz>
            <izz>0.00059816</izz>
          </inertia>
        </inertial>
        <collision name='j2s7s300_link_1_collision'>
          <pose frame=''>0 0 0 0 -0 0</pose>
          <geometry>
            <mesh>
              <scale>1 1 1</scale>
              <uri>/home/siqihu/MasterThesis/ma-siqi/ros_ws/src/kinova/kinova_description/meshes/shoulder.dae</uri>
            </mesh>
          </geometry>
          <max_contacts>10</max_contacts>
          <surface>
            <contact>
              <ode/>
            </contact>
            <bounce/>
            <friction>
              <torsional>
                <ode/>
              </torsional>
              <ode/>
            </friction>
          </surface>
        </collision>
        <visual name='j2s7s300_link_1_visual'>
          <pose frame=''>0 0 0 0 -0 0</pose>
          <geometry>
            <mesh>
              <scale>1 1 1</scale>
              <uri>/home/siqihu/MasterThesis/ma-siqi/ros_ws/src/kinova/kinova_description/meshes/shoulder.dae</uri>
            </mesh>
          </geometry>
        </visual>
        <visual name='j2s7s300_link_1_visual_1'>
          <pose frame=''>0 0 0 0 -0 0</pose>
          <geometry>
            <mesh>
              <scale>1 1 1</scale>
              <uri>/home/siqihu/MasterThesis/ma-siqi/ros_ws/src/kinova/kinova_description/meshes/ring_big.dae</uri>
            </mesh>
          </geometry>
        </visual>
        <self_collide>0</self_collide>
        <enable_wind>0</enable_wind>
        <kinematic>0</kinematic>
      </link>
      <joint name='j2s7s300_joint_1' type='revolute'>
        <child>j2s7s300_link_1</child>
        <parent>root</parent>
        <axis>
          <xyz>-0 0 -1</xyz>
          <limit>
            <lower>-1e+16</lower>
            <upper>1e+16</upper>
          </limit>
          <dynamics>
            <damping>0</damping>
            <friction>0</friction>
            <spring_reference>0</spring_reference>
            <spring_stiffness>0</spring_stiffness>
          </dynamics>
          <use_parent_model_frame>1</use_parent_model_frame>
        </axis>
        <physics>
          <provide_feedback>1</provide_feedback>
          <ode>
            <provide_feedback>1</provide_feedback>
            <limit>
              <cfm>0</cfm>
              <erp>0.2</erp>
            </limit>
          </ode>
        </physics>
      </joint>
      <link name='j2s7s300_link_2'>
        <pose frame=''>0 0.0016 0.2755 1.5708 -0 0</pose>
        <inertial>
          <pose frame=''>0 -0.103563 0 0 -0 0</pose>
          <mass>0.8447</mass>
          <inertia>
            <ixx>0.00247074</ixx>
            <ixy>0</ixy>
            <ixz>0</ixz>
            <iyy>0.000380115</iyy>
            <iyz>0</iyz>
            <izz>0.00247074</izz>
          </inertia>
        </inertial>
        <collision name='j2s7s300_link_2_collision'>
          <pose frame=''>0 0 0 0 -0 0</pose>
          <geometry>
            <mesh>
              <scale>1 1 1</scale>
              <uri>/home/siqihu/MasterThesis/ma-siqi/ros_ws/src/kinova/kinova_description/meshes/arm_half_1.dae</uri>
            </mesh>
          </geometry>
          <max_contacts>10</max_contacts>
          <surface>
            <contact>
              <ode/>
            </contact>
            <bounce/>
            <friction>
              <torsional>
                <ode/>
              </torsional>
              <ode/>
            </friction>
          </surface>
        </collision>
        <visual name='j2s7s300_link_2_visual'>
          <pose frame=''>0 0 0 0 -0 0</pose>
          <geometry>
            <mesh>
              <scale>1 1 1</scale>
              <uri>/home/siqihu/MasterThesis/ma-siqi/ros_ws/src/kinova/kinova_description/meshes/arm_half_1.dae</uri>
            </mesh>
          </geometry>
        </visual>
        <visual name='j2s7s300_link_2_visual_1'>
          <pose frame=''>0 0 0 0 -0 0</pose>
          <geometry>
            <mesh>
              <scale>1 1 1</scale>
              <uri>/home/siqihu/MasterThesis/ma-siqi/ros_ws/src/kinova/kinova_description/meshes/ring_big.dae</uri>
            </mesh>
          </geometry>
        </visual>
        <self_collide>0</self_collide>
        <enable_wind>0</enable_wind>
        <kinematic>0</kinematic>
      </link>
      <joint name='j2s7s300_joint_2' type='revolute'>
        <child>j2s7s300_link_2</child>
        <parent>j2s7s300_link_1</parent>
        <axis>
          <xyz>-0 -1 -0</xyz>
          <limit>
            <lower>0.820305</lower>
            <upper>5.46288</upper>
            <effort>80</effort>
            <velocity>0.628319</velocity>
          </limit>
          <dynamics>
            <damping>0</damping>
            <friction>0</friction>
            <spring_reference>0</spring_reference>
            <spring_stiffness>0</spring_stiffness>
          </dynamics>
          <use_parent_model_frame>1</use_parent_model_frame>
        </axis>
        <physics>
          <provide_feedback>1</provide_feedback>
          <ode>
            <provide_feedback>1</provide_feedback>
            <limit>
              <cfm>0</cfm>
              <erp>0.2</erp>
            </limit>
          </ode>
        </physics>
      </joint>
      <link name='j2s7s300_link_3'>
        <pose frame=''>-0 0.0016 0.0705 0 -0 0</pose>
        <inertial>
          <pose frame=''>0 0 -0.102245 0 -0 0</pose>
          <mass>0.8447</mass>
          <inertia>
            <ixx>0.00247074</ixx>
            <ixy>0</ixy>
            <ixz>0</ixz>
            <iyy>0.00247074</iyy>
            <iyz>0</iyz>
            <izz>0.000380115</izz>
          </inertia>
        </inertial>
        <collision name='j2s7s300_link_3_collision'>
          <pose frame=''>0 0 0 0 -0 0</pose>
          <geometry>
            <mesh>
              <scale>1 1 1</scale>
              <uri>/home/siqihu/MasterThesis/ma-siqi/ros_ws/src/kinova/kinova_description/meshes/arm_half_2.dae</uri>
            </mesh>
          </geometry>
          <max_contacts>10</max_contacts>
          <surface>
            <contact>
              <ode/>
            </contact>
            <bounce/>
            <friction>
              <torsional>
                <ode/>
              </torsional>
              <ode/>
            </friction>
          </surface>
        </collision>
        <visual name='j2s7s300_link_3_visual'>
          <pose frame=''>0 0 0 0 -0 0</pose>
          <geometry>
            <mesh>
              <scale>1 1 1</scale>
              <uri>/home/siqihu/MasterThesis/ma-siqi/ros_ws/src/kinova/kinova_description/meshes/arm_half_2.dae</uri>
            </mesh>
          </geometry>
        </visual>
        <visual name='j2s7s300_link_3_visual_1'>
          <pose frame=''>0 0 0 0 -0 0</pose>
          <geometry>
            <mesh>
              <scale>1 1 1</scale>
              <uri>/home/siqihu/MasterThesis/ma-siqi/ros_ws/src/kinova/kinova_description/meshes/ring_big.dae</uri>
            </mesh>
          </geometry>
        </visual>
        <self_collide>0</self_collide>
        <enable_wind>0</enable_wind>
        <kinematic>0</kinematic>
      </link>
      <joint name='j2s7s300_joint_3' type='revolute'>
        <child>j2s7s300_link_3</child>
        <parent>j2s7s300_link_2</parent>
        <axis>
          <xyz>0 -0 1</xyz>
          <limit>
            <lower>-1e+16</lower>
            <upper>1e+16</upper>
          </limit>
          <dynamics>
            <damping>0</damping>
            <friction>0</friction>
            <spring_reference>0</spring_reference>
            <spring_stiffness>0</spring_stiffness>
          </dynamics>
          <use_parent_model_frame>1</use_parent_model_frame>
        </axis>
        <physics>
          <provide_feedback>1</provide_feedback>
          <ode>
            <provide_feedback>1</provide_feedback>
            <limit>
              <cfm>0</cfm>
              <erp>0.2</erp>
            </limit>
          </ode>
        </physics>
      </joint>
      <link name='j2s7s300_link_4'>
        <pose frame=''>-0 0.0016 -0.1345 1.5708 -0 -3.14159</pose>
        <inertial>
          <pose frame=''>0 0.081 -0.0086 0 -0 0</pose>
          <mass>0.6763</mass>
          <inertia>
            <ixx>0.00142022</ixx>
            <ixy>0</ixy>
            <ixz>0</ixz>
            <iyy>0.000304335</iyy>
            <iyz>0</iyz>
            <izz>0.00142022</izz>
          </inertia>
        </inertial>
        <collision name='j2s7s300_link_4_collision'>
          <pose frame=''>0 0 0 0 -0 0</pose>
          <geometry>
            <mesh>
              <scale>1 1 1</scale>
              <uri>/home/siqihu/MasterThesis/ma-siqi/ros_ws/src/kinova/kinova_description/meshes/forearm.dae</uri>
            </mesh>
          </geometry>
          <max_contacts>10</max_contacts>
          <surface>
            <contact>
              <ode/>
            </contact>
            <bounce/>
            <friction>
              <torsional>
                <ode/>
              </torsional>
              <ode/>
            </friction>
          </surface>
        </collision>
        <visual name='j2s7s300_link_4_visual'>
          <pose frame=''>0 0 0 0 -0 0</pose>
          <geometry>
            <mesh>
              <scale>1 1 1</scale>
              <uri>/home/siqihu/MasterThesis/ma-siqi/ros_ws/src/kinova/kinova_description/meshes/forearm.dae</uri>
            </mesh>
          </geometry>
        </visual>
        <visual name='j2s7s300_link_4_visual_1'>
          <pose frame=''>0 0 0 0 -0 0</pose>
          <geometry>
            <mesh>
              <scale>1 1 1</scale>
              <uri>/home/siqihu/MasterThesis/ma-siqi/ros_ws/src/kinova/kinova_description/meshes/ring_small.dae</uri>
            </mesh>
          </geometry>
        </visual>
        <self_collide>0</self_collide>
        <enable_wind>0</enable_wind>
        <kinematic>0</kinematic>
      </link>
      <joint name='j2s7s300_joint_4' type='revolute'>
        <child>j2s7s300_link_4</child>
        <parent>j2s7s300_link_3</parent>
        <axis>
          <xyz>0 1 0</xyz>
          <limit>
            <lower>0.523599</lower>
            <upper>5.75959</upper>
            <effort>40</effort>
            <velocity>0.628319</velocity>
          </limit>
          <dynamics>
            <damping>0</damping>
            <friction>0</friction>
            <spring_reference>0</spring_reference>
            <spring_stiffness>0</spring_stiffness>
          </dynamics>
          <use_parent_model_frame>1</use_parent_model_frame>
        </axis>
        <physics>
          <provide_feedback>1</provide_feedback>
          <ode>
            <provide_feedback>1</provide_feedback>
            <limit>
              <cfm>0</cfm>
              <erp>0.2</erp>
            </limit>
          </ode>
        </physics>
      </joint>
      <link name='j2s7s300_link_5'>
        <pose frame=''>-0 -0.0098 0.0728 -3.14159 0 0</pose>
        <inertial>
          <pose frame=''>0 0.002885 -0.054193 0 -0 0</pose>
          <mass>0.463</mass>
          <inertia>
            <ixx>0.000432132</ixx>
            <ixy>0</ixy>
            <ixz>0</ixz>
            <iyy>0.000432132</iyy>
            <iyz>0</iyz>
            <izz>9.26e-05</izz>
          </inertia>
        </inertial>
        <collision name='j2s7s300_link_5_collision'>
          <pose frame=''>0 0 0 0 -0 0</pose>
          <geometry>
            <mesh>
              <scale>1 1 1</scale>
              <uri>/home/siqihu/MasterThesis/ma-siqi/ros_ws/src/kinova/kinova_description/meshes/wrist_spherical_1.dae</uri>
            </mesh>
          </geometry>
          <max_contacts>10</max_contacts>
          <surface>
            <contact>
              <ode/>
            </contact>
            <bounce/>
            <friction>
              <torsional>
                <ode/>
              </torsional>
              <ode/>
            </friction>
          </surface>
        </collision>
        <visual name='j2s7s300_link_5_visual'>
          <pose frame=''>0 0 0 0 -0 0</pose>
          <geometry>
            <mesh>
              <scale>1 1 1</scale>
              <uri>/home/siqihu/MasterThesis/ma-siqi/ros_ws/src/kinova/kinova_description/meshes/wrist_spherical_1.dae</uri>
            </mesh>
          </geometry>
        </visual>
        <visual name='j2s7s300_link_5_visual_1'>
          <pose frame=''>0 0 0 0 -0 0</pose>
          <geometry>
            <mesh>
              <scale>1 1 1</scale>
              <uri>/home/siqihu/MasterThesis/ma-siqi/ros_ws/src/kinova/kinova_description/meshes/ring_small.dae</uri>
            </mesh>
          </geometry>
        </visual>
        <self_collide>0</self_collide>
        <enable_wind>0</enable_wind>
        <kinematic>0</kinematic>
      </link>
      <joint name='j2s7s300_joint_5' type='revolute'>
        <child>j2s7s300_link_5</child>
        <parent>j2s7s300_link_4</parent>
        <axis>
          <xyz>-0 0 -1</xyz>
          <limit>
            <lower>-1e+16</lower>
            <upper>1e+16</upper>
          </limit>
          <dynamics>
            <damping>0</damping>
            <friction>0</friction>
            <spring_reference>0</spring_reference>
            <spring_stiffness>0</spring_stiffness>
          </dynamics>
          <use_parent_model_frame>1</use_parent_model_frame>
        </axis>
        <physics>
          <provide_feedback>1</provide_feedback>
          <ode>
            <provide_feedback>1</provide_feedback>
            <limit>
              <cfm>0</cfm>
              <erp>0.2</erp>
            </limit>
          </ode>
        </physics>
      </joint>
      <link name='j2s7s300_link_6'>
        <pose frame=''>0 -0.0098 0.17655 -1.5708 -0 3.14159</pose>
        <inertial>
          <pose frame=''>0 0.049721 -0.002856 0 -0 0</pose>
          <mass>0.463</mass>
          <inertia>
            <ixx>0.000432132</ixx>
            <ixy>0</ixy>
            <ixz>0</ixz>
            <iyy>9.26e-05</iyy>
            <iyz>0</iyz>
            <izz>0.000432132</izz>
          </inertia>
        </inertial>
        <collision name='j2s7s300_link_6_collision'>
          <pose frame=''>0 0 0 0 -0 0</pose>
          <geometry>
            <mesh>
              <scale>1 1 1</scale>
              <uri>/home/siqihu/MasterThesis/ma-siqi/ros_ws/src/kinova/kinova_description/meshes/wrist_spherical_2.dae</uri>
            </mesh>
          </geometry>
          <max_contacts>10</max_contacts>
          <surface>
            <contact>
              <ode/>
            </contact>
            <bounce/>
            <friction>
              <torsional>
                <ode/>
              </torsional>
              <ode/>
            </friction>
          </surface>
        </collision>
        <visual name='j2s7s300_link_6_visual'>
          <pose frame=''>0 0 0 0 -0 0</pose>
          <geometry>
            <mesh>
              <scale>1 1 1</scale>
              <uri>/home/siqihu/MasterThesis/ma-siqi/ros_ws/src/kinova/kinova_description/meshes/wrist_spherical_2.dae</uri>
            </mesh>
          </geometry>
        </visual>
        <visual name='j2s7s300_link_6_visual_1'>
          <pose frame=''>0 0 0 0 -0 0</pose>
          <geometry>
            <mesh>
              <scale>1 1 1</scale>
              <uri>/home/siqihu/MasterThesis/ma-siqi/ros_ws/src/kinova/kinova_description/meshes/ring_small.dae</uri>
            </mesh>
          </geometry>
        </visual>
        <self_collide>0</self_collide>
        <enable_wind>0</enable_wind>
        <kinematic>0</kinematic>
      </link>
      <joint name='j2s7s300_joint_6' type='revolute'>
        <child>j2s7s300_link_6</child>
        <parent>j2s7s300_link_5</parent>
        <axis>
          <xyz>-0 -1 -0</xyz>
          <limit>
            <lower>1.13446</lower>
            <upper>5.14872</upper>
            <effort>20</effort>
            <velocity>0.837758</velocity>
          </limit>
          <dynamics>
            <damping>0</damping>
            <friction>0</friction>
            <spring_reference>0</spring_reference>
            <spring_stiffness>0</spring_stiffness>
          </dynamics>
          <use_parent_model_frame>1</use_parent_model_frame>
        </axis>
        <physics>
          <provide_feedback>1</provide_feedback>
          <ode>
            <provide_feedback>1</provide_feedback>
            <limit>
              <cfm>0</cfm>
              <erp>0.2</erp>
            </limit>
          </ode>
        </physics>
      </joint>
      <link name='j2s7s300_link_7'>
        <pose frame=''>-0 -0.0098 0.0728 0 -0 0</pose>
        <inertial>
          <pose frame=''>0 0 -0.06 0 -0 0</pose>
          <mass>0.99</mass>
          <inertia>
            <ixx>0.000345324</ixx>
            <ixy>0</ixy>
            <ixz>0</ixz>
            <iyy>0.000345324</iyy>
            <iyz>0</iyz>
            <izz>0.0005816</izz>
          </inertia>
        </inertial>
        <collision name='j2s7s300_link_7_collision'>
          <pose frame=''>0 0 0 0 -0 0</pose>
          <geometry>
            <mesh>
              <scale>1 1 1</scale>
              <uri>/home/siqihu/MasterThesis/ma-siqi/ros_ws/src/kinova/kinova_description/meshes/hand_3finger.dae</uri>
            </mesh>
          </geometry>
          <max_contacts>10</max_contacts>
          <surface>
            <contact>
              <ode/>
            </contact>
            <bounce/>
            <friction>
              <torsional>
                <ode/>
              </torsional>
              <ode/>
            </friction>
          </surface>
        </collision>
        <visual name='j2s7s300_link_7_visual'>
          <pose frame=''>0 0 0 0 -0 0</pose>
          <geometry>
            <mesh>
              <scale>1 1 1</scale>
              <uri>/home/siqihu/MasterThesis/ma-siqi/ros_ws/src/kinova/kinova_description/meshes/hand_3finger.dae</uri>
            </mesh>
          </geometry>
        </visual>
        <visual name='j2s7s300_link_7_visual_1'>
          <pose frame=''>0 0 0 0 -0 0</pose>
          <geometry>
            <mesh>
              <scale>1 1 1</scale>
              <uri>/home/siqihu/MasterThesis/ma-siqi/ros_ws/src/kinova/kinova_description/meshes/ring_small.dae</uri>
            </mesh>
          </geometry>
        </visual>
        <self_collide>0</self_collide>
        <enable_wind>0</enable_wind>
        <kinematic>0</kinematic>
      </link>
      <joint name='j2s7s300_joint_7' type='revolute'>
        <child>j2s7s300_link_7</child>
        <parent>j2s7s300_link_6</parent>
        <axis>
          <xyz>0 -0 1</xyz>
          <limit>
            <lower>-1e+16</lower>
            <upper>1e+16</upper>
          </limit>
          <dynamics>
            <damping>0</damping>
            <friction>0</friction>
            <spring_reference>0</spring_reference>
            <spring_stiffness>0</spring_stiffness>
          </dynamics>
          <use_parent_model_frame>1</use_parent_model_frame>
        </axis>
        <physics>
          <provide_feedback>1</provide_feedback>
          <ode>
            <provide_feedback>1</provide_feedback>
            <limit>
              <cfm>0</cfm>
              <erp>0.2</erp>
            </limit>
          </ode>
        </physics>
      </joint>
      <link name='j2s7s300_link_finger_1'>
        <pose frame=''>0.00279 0.02146 -0.04187 -1.5708 0.649262 1.35961</pose>
        <inertial>
          <pose frame=''>0.022 0 0 0 -0 0</pose>
          <mass>0.01</mass>
          <inertia>
            <ixx>7.89997e-07</ixx>
            <ixy>0</ixy>
            <ixz>0</ixz>
            <iyy>7.89997e-07</iyy>
            <iyz>0</iyz>
            <izz>8e-08</izz>
          </inertia>
        </inertial>
        <collision name='j2s7s300_link_finger_1_collision'>
          <pose frame=''>0 0 0 0 -0 0</pose>
          <geometry>
            <mesh>
              <scale>1 1 1</scale>
              <uri>/home/siqihu/MasterThesis/ma-siqi/ros_ws/src/kinova/kinova_description/meshes/finger_proximal.dae</uri>
            </mesh>
          </geometry>
          <max_contacts>10</max_contacts>
          <surface>
            <contact>
              <ode/>
            </contact>
            <bounce/>
            <friction>
              <torsional>
                <ode/>
              </torsional>
              <ode/>
            </friction>
          </surface>
        </collision>
        <visual name='j2s7s300_link_finger_1_visual'>
          <pose frame=''>0 0 0 0 -0 0</pose>
          <geometry>
            <mesh>
              <scale>1 1 1</scale>
              <uri>/home/siqihu/MasterThesis/ma-siqi/ros_ws/src/kinova/kinova_description/meshes/finger_proximal.dae</uri>
            </mesh>
          </geometry>
        </visual>
        <self_collide>0</self_collide>
        <enable_wind>0</enable_wind>
        <kinematic>0</kinematic>
      </link>
      <joint name='j2s7s300_joint_finger_1' type='revolute'>
        <child>j2s7s300_link_finger_1</child>
        <parent>j2s7s300_link_7</parent>
        <axis>
          <xyz>-0.977783 0.209619 -0</xyz>
          <limit>
            <lower>0</lower>
            <upper>1.51</upper>
            <effort>2</effort>
            <velocity>1</velocity>
          </limit>
          <dynamics>
            <spring_reference>0</spring_reference>
            <spring_stiffness>0</spring_stiffness>
          </dynamics>
          <use_parent_model_frame>1</use_parent_model_frame>
        </axis>
      </joint>
      <link name='j2s7s300_link_finger_tip_1'>
        <pose frame=''>0.010517 0.057502 -0.066083 -1.5708 0.649262 1.35961</pose>
        <inertial>
          <pose frame=''>0.022 0 0 0 -0 0</pose>
          <mass>0.01</mass>
          <inertia>
            <ixx>7.89997e-07</ixx>
            <ixy>0</ixy>
            <ixz>0</ixz>
            <iyy>7.89997e-07</iyy>
            <iyz>0</iyz>
            <izz>8e-08</izz>
          </inertia>
        </inertial>
        <collision name='j2s7s300_link_finger_tip_1_collision'>
          <pose frame=''>0 0 0 0 -0 0</pose>
          <geometry>
            <mesh>
              <scale>1 1 1</scale>
              <uri>/home/siqihu/MasterThesis/ma-siqi/ros_ws/src/kinova/kinova_description/meshes/finger_distal.dae</uri>
            </mesh>
          </geometry>
          <max_contacts>10</max_contacts>
          <surface>
            <contact>
              <ode/>
            </contact>
            <bounce/>
            <friction>
              <torsional>
                <ode/>
              </torsional>
              <ode/>
            </friction>
          </surface>
        </collision>
        <visual name='j2s7s300_link_finger_tip_1_visual'>
          <pose frame=''>0 0 0 0 -0 0</pose>
          <geometry>
            <mesh>
              <scale>1 1 1</scale>
              <uri>/home/siqihu/MasterThesis/ma-siqi/ros_ws/src/kinova/kinova_description/meshes/finger_distal.dae</uri>
            </mesh>
          </geometry>
        </visual>
        <self_collide>0</self_collide>
        <enable_wind>0</enable_wind>
        <kinematic>0</kinematic>
      </link>
      <joint name='j2s7s300_joint_finger_tip_1' type='revolute'>
        <child>j2s7s300_link_finger_tip_1</child>
        <parent>j2s7s300_link_finger_1</parent>
        <axis>
          <xyz>-0.977783 0.209619 -0</xyz>
          <limit>
            <lower>0</lower>
            <upper>2</upper>
            <effort>2</effort>
            <velocity>1</velocity>
          </limit>
          <dynamics>
            <spring_reference>0</spring_reference>
            <spring_stiffness>0</spring_stiffness>
          </dynamics>
          <use_parent_model_frame>1</use_parent_model_frame>
        </axis>
      </joint>
      <link name='j2s7s300_link_finger_2'>
        <pose frame=''>0.02226 -0.03687 -0.04202 -1.5708 0.649262 -1.38614</pose>
        <inertial>
          <pose frame=''>0.022 0 0 0 -0 0</pose>
          <mass>0.01</mass>
          <inertia>
            <ixx>7.89997e-07</ixx>
            <ixy>0</ixy>
            <ixz>0</ixz>
            <iyy>7.89997e-07</iyy>
            <iyz>0</iyz>
            <izz>8e-08</izz>
          </inertia>
        </inertial>
        <collision name='j2s7s300_link_finger_2_collision'>
          <pose frame=''>0 0 0 0 -0 0</pose>
          <geometry>
            <mesh>
              <scale>1 1 1</scale>
              <uri>/home/siqihu/MasterThesis/ma-siqi/ros_ws/src/kinova/kinova_description/meshes/finger_proximal.dae</uri>
            </mesh>
          </geometry>
          <max_contacts>10</max_contacts>
          <surface>
            <contact>
              <ode/>
            </contact>
            <bounce/>
            <friction>
              <torsional>
                <ode/>
              </torsional>
              <ode/>
            </friction>
          </surface>
        </collision>
        <visual name='j2s7s300_link_finger_2_visual'>
          <pose frame=''>0 0 0 0 -0 0</pose>
          <geometry>
            <mesh>
              <scale>1 1 1</scale>
              <uri>/home/siqihu/MasterThesis/ma-siqi/ros_ws/src/kinova/kinova_description/meshes/finger_proximal.dae</uri>
            </mesh>
          </geometry>
        </visual>
        <self_collide>0</self_collide>
        <enable_wind>0</enable_wind>
        <kinematic>0</kinematic>
      </link>
      <joint name='j2s7s300_joint_finger_2' type='revolute'>
        <child>j2s7s300_link_finger_2</child>
        <parent>j2s7s300_link_7</parent>
        <axis>
          <xyz>0.983 0.183608 -0</xyz>
          <limit>
            <lower>0</lower>
            <upper>1.51</upper>
            <effort>2</effort>
            <velocity>1</velocity>
          </limit>
          <dynamics>
            <spring_reference>0</spring_reference>
            <spring_stiffness>0</spring_stiffness>
          </dynamics>
          <use_parent_model_frame>1</use_parent_model_frame>
        </axis>
      </joint>
      <link name='j2s7s300_link_finger_tip_2'>
        <pose frame=''>0.029028 -0.073105 -0.066233 -1.5708 0.649262 -1.38614</pose>
        <inertial>
          <pose frame=''>0.022 0 0 0 -0 0</pose>
          <mass>0.01</mass>
          <inertia>
            <ixx>7.89997e-07</ixx>
            <ixy>0</ixy>
            <ixz>0</ixz>
            <iyy>7.89997e-07</iyy>
            <iyz>0</iyz>
            <izz>8e-08</izz>
          </inertia>
        </inertial>
        <collision name='j2s7s300_link_finger_tip_2_collision'>
          <pose frame=''>0 0 0 0 -0 0</pose>
          <geometry>
            <mesh>
              <scale>1 1 1</scale>
              <uri>/home/siqihu/MasterThesis/ma-siqi/ros_ws/src/kinova/kinova_description/meshes/finger_distal.dae</uri>
            </mesh>
          </geometry>
          <max_contacts>10</max_contacts>
          <surface>
            <contact>
              <ode/>
            </contact>
            <bounce/>
            <friction>
              <torsional>
                <ode/>
              </torsional>
              <ode/>
            </friction>
          </surface>
        </collision>
        <visual name='j2s7s300_link_finger_tip_2_visual'>
          <pose frame=''>0 0 0 0 -0 0</pose>
          <geometry>
            <mesh>
              <scale>1 1 1</scale>
              <uri>/home/siqihu/MasterThesis/ma-siqi/ros_ws/src/kinova/kinova_description/meshes/finger_distal.dae</uri>
            </mesh>
          </geometry>
        </visual>
        <self_collide>0</self_collide>
        <enable_wind>0</enable_wind>
        <kinematic>0</kinematic>
      </link>
      <joint name='j2s7s300_joint_finger_tip_2' type='revolute'>
        <child>j2s7s300_link_finger_tip_2</child>
        <parent>j2s7s300_link_finger_2</parent>
        <axis>
          <xyz>0.983 0.183608 -0</xyz>
          <limit>
            <lower>0</lower>
            <upper>2</upper>
            <effort>2</effort>
            <velocity>1</velocity>
          </limit>
          <dynamics>
            <spring_reference>0</spring_reference>
            <spring_stiffness>0</spring_stiffness>
          </dynamics>
          <use_parent_model_frame>1</use_parent_model_frame>
        </axis>
      </joint>
      <link name='j2s7s300_link_finger_3'>
        <pose frame=''>-0.02226 -0.03687 -0.04202 -1.5708 0.649262 -1.75545</pose>
        <inertial>
          <pose frame=''>0.022 0 0 0 -0 0</pose>
          <mass>0.01</mass>
          <inertia>
            <ixx>7.89997e-07</ixx>
            <ixy>0</ixy>
            <ixz>0</ixz>
            <iyy>7.89997e-07</iyy>
            <iyz>0</iyz>
            <izz>8e-08</izz>
          </inertia>
        </inertial>
        <collision name='j2s7s300_link_finger_3_collision'>
          <pose frame=''>0 0 0 0 -0 0</pose>
          <geometry>
            <mesh>
              <scale>1 1 1</scale>
              <uri>/home/siqihu/MasterThesis/ma-siqi/ros_ws/src/kinova/kinova_description/meshes/finger_proximal.dae</uri>
            </mesh>
          </geometry>
          <max_contacts>10</max_contacts>
          <surface>
            <contact>
              <ode/>
            </contact>
            <bounce/>
            <friction>
              <torsional>
                <ode/>
              </torsional>
              <ode/>
            </friction>
          </surface>
        </collision>
        <visual name='j2s7s300_link_finger_3_visual'>
          <pose frame=''>0 0 0 0 -0 0</pose>
          <geometry>
            <mesh>
              <scale>1 1 1</scale>
              <uri>/home/siqihu/MasterThesis/ma-siqi/ros_ws/src/kinova/kinova_description/meshes/finger_proximal.dae</uri>
            </mesh>
          </geometry>
        </visual>
        <self_collide>0</self_collide>
        <enable_wind>0</enable_wind>
        <kinematic>0</kinematic>
      </link>
      <joint name='j2s7s300_joint_finger_3' type='revolute'>
        <child>j2s7s300_link_finger_3</child>
        <parent>j2s7s300_link_7</parent>
        <axis>
          <xyz>0.983 -0.183608 -0</xyz>
          <limit>
            <lower>0</lower>
            <upper>1.51</upper>
            <effort>2</effort>
            <velocity>1</velocity>
          </limit>
          <dynamics>
            <spring_reference>0</spring_reference>
            <spring_stiffness>0</spring_stiffness>
          </dynamics>
          <use_parent_model_frame>1</use_parent_model_frame>
        </axis>
      </joint>
      <link name='j2s7s300_link_finger_tip_3'>
        <pose frame=''>-0.029028 -0.073105 -0.066233 -1.5708 0.649262 -1.75545</pose>
        <inertial>
          <pose frame=''>0.022 0 0 0 -0 0</pose>
          <mass>0.01</mass>
          <inertia>
            <ixx>7.89997e-07</ixx>
            <ixy>0</ixy>
            <ixz>0</ixz>
            <iyy>7.89997e-07</iyy>
            <iyz>0</iyz>
            <izz>8e-08</izz>
          </inertia>
        </inertial>
        <collision name='j2s7s300_link_finger_tip_3_collision'>
          <pose frame=''>0 0 0 0 -0 0</pose>
          <geometry>
            <mesh>
              <scale>1 1 1</scale>
              <uri>/home/siqihu/MasterThesis/ma-siqi/ros_ws/src/kinova/kinova_description/meshes/finger_distal.dae</uri>
            </mesh>
          </geometry>
          <max_contacts>10</max_contacts>
          <surface>
            <contact>
              <ode/>
            </contact>
            <bounce/>
            <friction>
              <torsional>
                <ode/>
              </torsional>
              <ode/>
            </friction>
          </surface>
        </collision>
        <visual name='j2s7s300_link_finger_tip_3_visual'>
          <pose frame=''>0 0 0 0 -0 0</pose>
          <geometry>
            <mesh>
              <scale>1 1 1</scale>
              <uri>/home/siqihu/MasterThesis/ma-siqi/ros_ws/src/kinova/kinova_description/meshes/finger_distal.dae</uri>
            </mesh>
          </geometry>
        </visual>
        <self_collide>0</self_collide>
        <enable_wind>0</enable_wind>
        <kinematic>0</kinematic>
      </link>
      <joint name='j2s7s300_joint_finger_tip_3' type='revolute'>
        <child>j2s7s300_link_finger_tip_3</child>
        <parent>j2s7s300_link_finger_3</parent>
        <axis>
          <xyz>0.983 -0.183608 -0</xyz>
          <limit>
            <lower>0</lower>
            <upper>2</upper>
            <effort>2</effort>
            <velocity>1</velocity>
          </limit>
          <dynamics>
            <spring_reference>0</spring_reference>
            <spring_stiffness>0</spring_stiffness>
          </dynamics>
          <use_parent_model_frame>1</use_parent_model_frame>
        </axis>
      </joint>
      <plugin name='gazebo_ros_control' filename='libgazebo_ros_control.so'>
        <robotNamespace>j2s7s300</robotNamespace>
        <robotSimType>gazebo_ros_control/DefaultRobotHWSim</robotSimType>
        <legacyModeNS>1</legacyModeNS>
      </plugin>
      <plugin name='ft_sensor' filename='libgazebo_ros_ft_sensor.so'>
        <updateRate>30.0</updateRate>
        <topicName>j2s7s300_joint_1_ft_sensor_topic</topicName>
        <jointName>j2s7s300_joint_1</jointName>
        <robotNamespace>/</robotNamespace>
      </plugin>
      <plugin name='ft_sensor' filename='libgazebo_ros_ft_sensor.so'>
        <updateRate>30.0</updateRate>
        <topicName>j2s7s300_joint_2_ft_sensor_topic</topicName>
        <jointName>j2s7s300_joint_2</jointName>
        <robotNamespace>/</robotNamespace>
      </plugin>
      <plugin name='ft_sensor' filename='libgazebo_ros_ft_sensor.so'>
        <updateRate>30.0</updateRate>
        <topicName>j2s7s300_joint_3_ft_sensor_topic</topicName>
        <jointName>j2s7s300_joint_3</jointName>
        <robotNamespace>/</robotNamespace>
      </plugin>
      <plugin name='ft_sensor' filename='libgazebo_ros_ft_sensor.so'>
        <updateRate>30.0</updateRate>
        <topicName>j2s7s300_joint_4_ft_sensor_topic</topicName>
        <jointName>j2s7s300_joint_4</jointName>
        <robotNamespace>/</robotNamespace>
      </plugin>
      <plugin name='ft_sensor' filename='libgazebo_ros_ft_sensor.so'>
        <updateRate>30.0</updateRate>
        <topicName>j2s7s300_joint_5_ft_sensor_topic</topicName>
        <jointName>j2s7s300_joint_5</jointName>
        <robotNamespace>/</robotNamespace>
      </plugin>
      <plugin name='ft_sensor' filename='libgazebo_ros_ft_sensor.so'>
        <updateRate>30.0</updateRate>
        <topicName>j2s7s300_joint_6_ft_sensor_topic</topicName>
        <jointName>j2s7s300_joint_6</jointName>
        <robotNamespace>/</robotNamespace>
      </plugin>
      <static>0</static>
      <plugin name='ft_sensor' filename='libgazebo_ros_ft_sensor.so'>
        <updateRate>30.0</updateRate>
        <topicName>j2s7s300_joint_7_ft_sensor_topic</topicName>
        <jointName>j2s7s300_joint_7</jointName>
        <robotNamespace>/</robotNamespace>
      </plugin>
      <pose frame=''>0 0 0 0 -0 0</pose>
    </model>
    <model name='kinect'>
      <pose frame=''>-0.949121 -0.994972 0.036 0 -0 0</pose>
      <link name='link'>
        <inertial>
          <mass>0.1</mass>
          <pose frame=''>0 0 0 0 -0 0</pose>
          <inertia>
            <ixx>1</ixx>
            <ixy>0</ixy>
            <ixz>0</ixz>
            <iyy>1</iyy>
            <iyz>0</iyz>
            <izz>1</izz>
          </inertia>
        </inertial>
        <collision name='collision'>
          <geometry>
            <box>
              <size>0.073 0.276 0.072</size>
            </box>
          </geometry>
          <max_contacts>10</max_contacts>
          <surface>
            <contact>
              <ode/>
            </contact>
            <bounce/>
            <friction>
              <torsional>
                <ode/>
              </torsional>
              <ode/>
            </friction>
          </surface>
        </collision>
        <visual name='visual'>
          <geometry>
            <mesh>
              <uri>model://kinect/meshes/kinect.dae</uri>
            </mesh>
          </geometry>
        </visual>
        <sensor name='camera' type='depth'>
          <update_rate>20</update_rate>
          <camera name='__default__'>
            <horizontal_fov>1.0472</horizontal_fov>
            <image>
              <width>640</width>
              <height>480</height>
              <format>R8G8B8</format>
            </image>
            <clip>
              <near>0.05</near>
              <far>3</far>
            </clip>
          </camera>
          <plugin name='camera_plugin' filename='libgazebo_ros_openni_kinect.so'>
            <baseline>0.2</baseline>
            <alwaysOn>1</alwaysOn>
            <updateRate>0.0</updateRate>
            <cameraName>camera_ir</cameraName>
            <imageTopicName>/camera/color/image_raw</imageTopicName>
            <cameraInfoTopicName>/camera/color/camera_info</cameraInfoTopicName>
            <depthImageTopicName>/camera/depth/image_raw</depthImageTopicName>
            <depthImageCameraInfoTopicName>/camera/depth/camera_info</depthImageCameraInfoTopicName>
            <pointCloudTopicName>/camera/depth/points</pointCloudTopicName>
            <frameName>camera_link</frameName>
            <pointCloudCutoff>0.5</pointCloudCutoff>
            <pointCloudCutoffMax>3.0</pointCloudCutoffMax>
            <distortionK1>0</distortionK1>
            <distortionK2>0</distortionK2>
            <distortionK3>0</distortionK3>
            <distortionT1>0</distortionT1>
            <distortionT2>0</distortionT2>
            <CxPrime>0</CxPrime>
            <Cx>0</Cx>
            <Cy>0</Cy>
            <focalLength>0</focalLength>
            <hackBaseline>0</hackBaseline>
          </plugin>
        </sensor>
        <self_collide>0</self_collide>
        <enable_wind>0</enable_wind>
        <kinematic>1</kinematic>
      </link>
    </model>
  </world>
</sdf>
